Workbook

Sheet Raw_Data
A1: product_id | B1: product_name | C1: category | D1: discounted_price | E1: actual_price | F1: discount_percentage | G1: rating | H1: rating_count | I1: about_product | J1: user_id | K1: user_name | L1: review_id | M1: review_title | N1: review_content | O1: img_link | P1: product_link
A2: B07JW9H4J1 | B2: Wayona Nylon Braided USB to Lightning Fast Charging and Data Sync Cable Compatible for iPhone 13, 12,11, X, 8, 7, 6, 5, iPad Air, Pro, Mini (3 FT Pack of 1, Grey) | C2: Computers&Accessories|Accessories&Peripherals|Cables&Accessories|Cables|USBCables | D2: â‚¹399 | E2: â‚¹1,099 | F2: 0.64 | G2: 4.2 | H2: 24269 | I2: High Compatibility : Compatible With iPhone 12, 11, X/XsMax/Xr ,iPhone 8/8 Plus,iPhone 7/7 Plus,iPhone 6s/6s Plus,iPhone 6/6 Plus,iPhone 5/5s/5c/se,iPad Pro,iPad Air 1/2,iPad mini 1/2/3,iPod nano7,iPod touch and more apple devices.|Fast Charge&Data Sync : It can charge and sync simultaneously at a rapid speed, Compatible with any charging adaptor, multi-port charging station or power bank.|Durability : Durable nylon braided design with premium aluminum housing and toughened nylon fiber wound tightly around the cord lending it superior durability and adding a bit to its flexibility.|High Security Level : It is designed to fully protect your device from damaging excessive current.Copper core thick+Multilayer shielding, Anti-interference, Protective circuit equipment.|WARRANTY: 12 months warranty and friendly customer services, ensures the long-time enjoyment of your purchase. If you meet any question or problem, please don't hesitate to contact us. | J2: AG3D6O4STAQKAY2UVGEUV46KN35Q,AHMY5CWJMMK5BJRBBSNLYT3ONILA,AHCTC6ULH4XB6YHDY6PCH2R772LQ,AGYHHIERNXKA6P5T7CZLXKVPT7IQ,AG4OGOFWXJZTQ2HKYIOCOY3KXF2Q,AENGU523SXMOS7JPDTW52PNNVWGQ,AEQJHCVTNINBS4FKTBGQRQTGTE5Q,AFC3FFC5PKFF5PMA52S3VCHOZ5FQ | K2: Manav,Adarsh gupta,Sundeep,S.Sayeed Ahmed,jaspreet singh,Khaja moin,Anand,S.ARUMUGAM | L2: R3HXWT0LRP0NMF,R2AJM3LFTLZHFO,R6AQJGUP6P86,R1KD19VHEDV0OR,R3C02RMYQMK6FC,R39GQRVBUZBWGY,R2K9EDOE15QIRJ,R3OI7YT648TL8I | M2: Satisfied,Charging is really fast,Value for money,Product review,Good quality,Good product,Good Product,As of now seems good | N2: Looks durable Charging is fine tooNo complains,Charging is really fast, good product.,Till now satisfied with the quality.,This is a good product . The charging speed is slower than the original iPhone cable,Good quality, would recommend,https://m.media-amazon.com/images/W/WEBP_402378-T1/images/I/81---F1ZgHL._SY88.jpg,Product had worked well till date and was having no issue.Cable is also sturdy enough...Have asked for replacement and company is doing the same...,Value for money | O2: https://m.media-amazon.com/images/W/WEBP_402378-T1/images/I/51UsScvHQNL._SX300_SY300_QL70_FMwebp_.jpg | P2: https://www.amazon.in/Wayona-Braided-WN3LG1-Syncing-Charging/dp/B07JW9H4J1/ref=sr_1_1?qid=1672909124&s=electronics&sr=1-1
A3: B098NS6PVG | B3: Ambrane Unbreakable 60W / 3A Fast Charging 1.5m Braided Type C Cable for Smartphones, Tablets, Laptops & other Type C devices, PD Technology, 480Mbps Data Sync, Quick Charge 3.0 (RCT15A, Black) | C3: Computers&Accessories|Accessories&Peripherals|Cables&Accessories|Cables|USBCables | D3: â‚¹199 | E3: â‚¹349 | F3: 0.43 | G3: 4 | H3: 43994 | I3: Compatible with all Type C enabled devices, be it an android smartphone (Mi, Samsung, Oppo, Vivo, Realme, OnePlus, etc), tablet, laptop (Macbook, Chromebook, etc)|Supports Quick Charging (2.0/3.0)|Unbreakable â€“ Made of special braided outer with rugged interior bindings, it is ultra-durable cable that wonâ€™t be affected by daily rough usage|Ideal Length â€“ It has ideal length of 1.5 meters which is neither too short like your typical 1meter cable or too long like a 2meters cable|Supports maximum 3A fast charging and 480 Mbps data transfer speed|6 months manufacturer warranty from the date of purchase | J3: AECPFYFQVRUWC3KGNLJIOREFP5LQ,AGYYVPDD7YG7FYNBXNGXZJT525AQ,AHONIZU3ICIEHQIGQ6R2VFRSBXOQ,AFPHD2CRPDZMWMBL7WXRSVYWS5JA,AEZ346GX3HJ4O4XNRPHCNHXQURMQ,AEPSWFPNECKO34PUC7I56ITGXR6Q,AHWVEHR5DYLVFTO2KF3IZATFQSWQ,AH4QT33M55677I7ISQOAKEQWACYQ | K3: ArdKn,Nirbhay kumar,Sagar Viswanathan,Asp,Placeholder,BharanI,sonia,Niam | L3: RGIQEG07R9HS2,R1SMWZQ86XIN8U,R2J3Y1WL29GWDE,RYGGS0M09S3KY,R17KQRUTAN5DKS,R3AAQGS6HP2QUK,R1HDNOG6TO2CCA,R3PHKXYA5AFEOU | M3: A Good Braided Cable for Your Type C Device,Good quality product from ambrane,Super cable,As,Good quality,Good product,its good,Good quality for the price but one issue with my unit | N3: I ordered this cable to connect my phone to Android Auto of car. The cable is really strong and the connection ports are really well made. I already has a Micro USB cable from Ambrane and it's still in good shape. I connected my phone to the car using the cable and it got connected well and no issues. I also connected it to the charging port and yes it has Fast Charging support.,It quality is good at this price and the main thing is that i didn't ever thought that this cable will be so long it's good one and charging power is too good and also supports fast charging,Value for money, with extra lengthðŸ‘,Good, working fine,Product quality is good,Good,very good,Bought for my daughter's old phone.Brand new cable it was not charging, I already repacked and requested for replacement.I checked again, and there was some green colour paste/fungus inside the micro USB connector. I cleaned with an alcoholic and starts working again.Checked the ampere of charging speed got around 1400ma-1500ma - not bad, came with braided 1.5m long cable, pretty impressive for the price.Can't blame the manufacturer.But quality issues by the distributor, they might have stored in very humid place. | O3: https://m.media-amazon.com/images/W/WEBP_402378-T2/images/I/31zOsqQOAOL._SY445_SX342_QL70_FMwebp_.jpg | P3: https://www.amazon.in/Ambrane-Unbreakable-Charging-Braided-Cable/dp/B098NS6PVG/ref=sr_1_2?qid=1672909124&s=electronics&sr=1-2
A4: B096MSW6CT | B4: Sounce Fast Phone Charging Cable & Data Sync USB Cable Compatible for iPhone 13, 12,11, X, 8, 7, 6, 5, iPad Air, Pro, Mini & iOS Devices | C4: Computers&Accessories|Accessories&Peripherals|Cables&Accessories|Cables|USBCables | D4: â‚¹199 | E4: â‚¹1,899 | F4: 0.9 | G4: 3.9 | H4: 7928 | I4: ã€ Fast Charger& Data Syncã€‘-With built-in safety proctections and four-core copper wires promote maximum signal quality and strength and enhance charging & data transfer speed with up to 480 mb/s transferring speed.|ã€ Compatibilityã€‘-Compatible with iPhone 13, 12,11, X, 8, 7, 6, 5, iPad Air, Pro, Mini & iOS devices.|ã€ Sturdy & Durableã€‘-The jacket and enforced connector made of TPE and premium copper, are resistant to repeatedly bending and coiling.|ã€ Ultra High Qualityã€‘: According to the experimental results, the fishbone design can accept at least 20,000 bending and insertion tests for extra protection and durability. Upgraded 3D aluminum connector and exclusive laser welding technology, which to ensure the metal part won't break and also have a tighter connection which fits well even with a protective case on and will never loose connection.|ã€ Good After Sales Serviceã€‘-Our friendly and reliable customer service will respond to you within 24 hours ! you can purchase with confidence,and every sale includes a 365-day worry-free Service to prove the importance we set on quality. | J4: AGU3BBQ2V2DDAMOAKGFAWDDQ6QHA,AESFLDV2PT363T2AQLWQOWZ4N3OA,AHTPQRIMGUD4BYR5YIHBH3CCGEFQ,AEUVWXYP5LT7PZLLZENEO2NODPBQ,AHC7MPW55DOO6WNCOQVA2VHOD26A,AFDI6FRPFBTNBG7BAEB7JDJSMKDQ,AFQKCEEEKXCOHTDG4WUN3XPPHJQQ,AHKUUFNMBZIDLSSPA4FEHIO2EC7Q | K4: Kunal,Himanshu,viswanath,sai niharka,saqib malik,Aashiq,Ramu Challa,Sanjay gupta | L4: R3J3EQQ9TZI5ZJ,R3E7WBGK7ID0KV,RWU79XKQ6I1QF,R25X4TBMPY91LX,R27OK7G99VK0TR,R207CYDCHJJTCJ,R3PCU8XMU173BT,R1IMONDOWRNU5V | M4: Good speed for earlier versions,Good Product,Working good,Good for the price,Good,Worth for money,Working nice,it's a really nice product | N4: Not quite durable and sturdy,https://m.media-amazon.com/images/W/WEBP_402378-T1/images/I/71rIggrbUCL._SY88.jpg,Working good,https://m.media-amazon.com/images/W/WEBP_402378-T1/images/I/61bKp9YO6wL._SY88.jpg,Product,Very nice product,Working well,It's a really nice product | O4: https://m.media-amazon.com/images/W/WEBP_402378-T1/images/I/31IvNJZnmdL._SY445_SX342_QL70_FMwebp_.jpg | P4: https://www.amazon.in/Sounce-iPhone-Charging-Compatible-Devices/dp/B096MSW6CT/ref=sr_1_3?qid=1672909124&s=electronics&sr=1-3
A5: B08HDJ86NZ | B5: boAt Deuce USB 300 2 in 1 Type-C & Micro USB Stress Resistant, Tangle-Free, Sturdy Cable with 3A Fast Charging & 480mbps Data Transmission, 10000+ Bends Lifespan and Extended 1.5m Length(Martian Red) | C5: Computers&Accessories|Accessories&Peripherals|Cables&Accessories|Cables|USBCables | D5: â‚¹329 | E5: â‚¹699 | F5: 0.53 | G5: 4.2 | H5: 94363 | I5: The boAt Deuce USB 300 2 in 1 cable is compatible with smartphones, tablets, PC peripherals, Bluetooth speakers, power banks and all other devices with Type-C as well as Micro USB port|It ensures 3A fast charging and data transmissions with rapid sync at 480 mbps|The premium Nylon braided skin makes it sturdy and invincible against external damage|Its Aluminium alloy shell housing makes it last longer with 10000+ Bends Lifespan with extended frame protection for strain relief|The resilient and flexible design offers a tangle free experience seamlessly|Deuce USB 300 cable offers a perfect 1.5 meters in length for smooth & hassle-free user experience|2 years warranty from the date of purchase | J5: AEWAZDZZJLQUYVOVGBEUKSLXHQ5A,AG5HTSFRRE6NL3M5SGCUQBP7YSCA,AH725ST5NW2Y4JZPKUNTIJCUK2BA,AHV3TXIFCJPMS4D5JATCEUR266MQ,AGWIGDEMFIIUAOXYY2QATNBSUGHA,AFSTSLQUV4EVEXWKBOLEFHL2H5YQ,AGAKDNBHY2FKX7I4ACRGILU7QL7A,AFNWJUWJRHCC6HN52KMG5AKZY37Q | K5: Omkar dhale,JD,HEMALATHA,Ajwadh a.,amar singh chouhan,Ravi Siddan,Himanshu Goel,Udaykumar | L5: R3EEUZKKK9J36I,R3HJVYCLYOY554,REDECAZ7AMPQC,R1CLH2ULIVG5U3,R2DMKIBGFKBD6R,RC89B5IAJUTR5,R3B3DDON5FH8DS,R13WAEJDI5RS36 | M5: Good product,Good one,Nice,Really nice product,Very first time change,Good,Fine product but could be better,Very nice it's charging like jet | N5: Good product,long wire,Charges good,Nice,I bought this cable for Rs.339 worthy product for this price, i tested it in various charger adapters 33w and 18w it supports fast charging as well.,Good,Ok,I had got this at good price on sale on Amazon and product is useful with warranty but for warranty you need to go very far not practical for such a cost and mine micro to type c connector stopped working after few days only.,I like this product | O5: https://m.media-amazon.com/images/I/41V5FtEWPkL._SX300_SY300_QL70_FMwebp_.jpg | P5: https://www.amazon.in/Deuce-300-Resistant-Tangle-Free-Transmission/dp/B08HDJ86NZ/ref=sr_1_4?qid=1672909124&s=electronics&sr=1-4
A6: B08CF3B7N1 | B6: Portronics Konnect L 1.2M Fast Charging 3A 8 Pin USB Cable with Charge & Sync Function for iPhone, iPad (Grey) | C6: Computers&Accessories|Accessories&Peripherals|Cables&Accessories|Cables|USBCables | D6: â‚¹154 | E6: â‚¹399 | F6: 0.61 | G6: 4.2 | H6: 16905 | I6: [CHARGE & SYNC FUNCTION]- This cable comes with charging & Data sync function|[HIGH QUALITY MATERIAL]- TPE + Nylon Material to make sure that the life of the cable is enhanced significantly|[LONG CORD]- The Cable is extra thick 1.2 meter long, optimized for an easy use for your comfort at home or office|[MORE DURABLE]-This cable is unique interms of design and multi-use and is positioned to provide the best comfort and performance while using|[UNIVERSAL COMPATIBILITY]- Compatible with all devices like iPhone XS, X, XR, 8, 7, 6S, 6, 5S, iPad Pro, iPad mini and iPad Air | J6: AE3Q6KSUK5P75D5HFYHCRAOLODSA,AFUGIFH5ZAFXRDSZHM4QB2KPKFUQ,AFK4NJOLFSJGWLOJIUIAROJF6YVA,AFUOTYRFUXVPEBGIXVZZ7DR3CZUA,AFDLRSXKDZ6U3U3KD46SQLFGZQRA,AH5VLM66SIK7J3IRG4NY7XVOQ55A,AE3MQNNHHLUHXURL5S7IAR7JTGNQ,AFSEOFZY67MYC7UAJU264Z5NFTLA | K6: rahuls6099,Swasat Borah,Ajay Wadke,Pranali,RVK,Bhargav,Durai Vignesh,Amazon Customer | L6: R1BP4L2HH9TFUP,R16PVJEXKV6QZS,R2UPDB81N66T4P,R3KK4GT934ST3I,RCFHMWUSBIJO,RDO7DACXMAJ84,R3A6MEZL3LY66Z,R1ESIEKPGAYA29 | M6: As good as original,Decent,Good one for secondary use,Best quality,GOOD,Amazing product at a mind blowing price!,Nice Quality,Good product | N6: Bought this instead of original apple, does the work for 150rs, not as fast as apple charger but its a good option if you want cheap and good product, bought it for iPad pro 10.5 and it's working flawlessly, build quality is ok, its not like i am gonna hang my clothes on it and i want a very strong cable, even a braided cable stop working after a year, i have used both Anker and Apple store strong braided cable they all stop working after a year so please don't buy high end cables just for that instead choose a this one and even if it's stops working withing a year you only loose 150rs compares to 2000rs.UPDATE------------------------------------pin has stopped charging from one side, now i have to slip the pin to charge from other side, but i will update and let know for how long does it work,,Itâ€™s good. Not sure about durability as the pin area feels a bit fragile,Does not support apple carplaySo was little disappointed about thatOther than that cable is made up of very good quality,Best to buy,100% NOT FATHFUL,Writing this review post 10 months and 3 orders of the same product.Honestly Portronics Konnect L lightning cable works like magic with the original Apple charging brick.Seeing the price of the cable I initially hesitated buying as it was as low as â‚¹99/- with the offers and so I wasnâ€™t sure if it would work well with my iPhone 12 or whether it would impact my iPhoneâ€™s battery health because all the other lightning cable brands were costing over â‚¹350/- like Wayona, Amazon Basics, etc.Earlier I was using Wayona Brand lightning cable with eventually frayed and stopped working.Charging Speed:Charges my iPhone fast enough almost similar compared to the original cable level when used with 12W Original Apple power adapter.Quality and Durability:Great quality braided cable and doesnâ€™t tangle easily and can withstand day-to-day usage.L-Shaped pin:This is very innovative by Portronics and it makes sure the cable doesnâ€™t get damaged even if used while charging.CarPlay and Data Sync:Works smoothly with CarPlay and syncs data effortlessly.PS: I have used this cable only with the Original Apple Charging Brick and extremely satisfied with its performance.,Better than I expect the product I like that Quality and I plan to buy same type cable come with usb C to Lighting cable for emergency purpose that much I love this cable. Buy for this cable only emergency uses only since Good one,Good product and value for money | O6: https://m.media-amazon.com/images/W/WEBP_402378-T2/images/I/31VzNhhqifL._SX300_SY300_QL70_FMwebp_.jpg | P6: https://www.amazon.in/Portronics-Konnect-POR-1080-Charging-Function/dp/B08CF3B7N1/ref=sr_1_5?qid=1672909124&s=electronics&sr=1-5
A7: B08Y1TFSP6 | B7: pTron Solero TB301 3A Type-C Data and Fast Charging Cable, Made in India, 480Mbps Data Sync, Strong and Durable 1.5-Meter Nylon Braided USB Cable for Type-C Devices for Charging Adapter (Black) | C7: Computers&Accessories|Accessories&Peripherals|Cables&Accessories|Cables|USBCables | D7: â‚¹149 | E7: â‚¹1,000 | F7: 0.85 | G7: 3.9 | H7: 24871 | I7: Fast Charging & Data Sync: Solero TB301 Type-C cable supports fast charge up to 5V/3A for devices and data syncing speed up to 480Mbps.|Universal Compatibility: This USB charging cable connects USB Type-C devices with standard USB devices like laptops, hard drives, power banks, wall and car chargers, etc..Connector One: Reversible Type C|Connector Two: USB A Type|Rough & Tough Type-C Cable: Charging cable with a double-braided exterior, premium aramid fiber core and metal plugs. It has passed 10,000 bending tests and can easily withstand daily use.|Extended Length: 1.5-meter long c-type cable uses nylon material to protect the wire and avoid knots.|Perfect Fit Connectors: pTron Soler USB-C has passed the 5KG load test, swing test, 5000+ times connect & disconnect to ensure that there are no loose connections. | J7: AEQ2YMXSZWEOHK2EHTNLOS56YTZQ,AGRVINWECNY7323CWFXZYYIZOFTQ,AHBAT6VLOXWGYDL57KHCNCLPXAKA,AF7NDY2H6JVYTSQOZP76GCATQ34Q,AFV7ZA733ZLME4KNLZPMPCBUNPPA,AHFAAPSY2MJ5HYOU2VQDJ7AQY4NQ,AH2WGV2PEBUTICRPBEEVKF24G5LA,AEP4MK3EKOBDKTGPJTRN5RBDIODA | K7: Jayesh,Rajesh k.,Soopy,amazon customer,Aman,Shankar,dinesh,Chitra,Ajaybabu.O.M | L7: R7S8ANNSDPR40,R3CLZFLHVJU26P,RFF7U7MPQFUGR,R1MV1NKC23DWPI,R11D3U0V2XKDKF,R18MP1KLUE18PC,RWGJNVEH5ZQME,R1XN72FU6Q37IH | M7: It's pretty good,Average quality,very good and useful usb cable,Good USB cable. My experience was very good it is long lasting,Good,Nice product and useful,-,Sturdy but does not support 33w charging | N7: It's a good product.,Like,Very good item strong and useful USB cableValue for moneyThanks to amazon and producer,https://m.media-amazon.com/images/I/51112ZRE-1L._SY88.jpg,Good,Nice product and useful product,-,Sturdy but does not support 33w charging | O7: https://m.media-amazon.com/images/I/31wOPjcSxlL._SX300_SY300_QL70_FMwebp_.jpg | P7: https://www.amazon.in/Solero-TB301-Charging-480Mbps-1-5-Meter/dp/B08Y1TFSP6/ref=sr_1_6?qid=1672909124&s=electronics&sr=1-6
A8: B08WRWPM22 | B8: boAt Micro USB 55 Tangle-free, Sturdy Micro USB Cable with 3A Fast Charging & 480mbps Data Transmission (Black) | C8: Computers&Accessories|Accessories&Peripherals|Cables&Accessories|Cables|USBCables | D8: â‚¹176.63 | E8: â‚¹499 | F8: 0.65 | G8: 4.1 | H8: 15188 | I8: It Ensures High Speed Transmission And Charging By Offering 3A Fast Charging And Data Transmissions With Rapid Sync At 480 Mbps|The Braided Skin Makes It Durable And Invincible Against External Damage So You Can Have An Absolute Hassle-Free & Tangle Free Experience|Its Durable Pvc Housing And The Flexible Design Makes It Last 6 Times Longer Than Other Cables|Usb Cable Offers A Perfect 1.5 Meters In Length For Smooth & Hassle-Free User Experience For Superior Charging & Data Transfer Tasks|The Compact And Smooth Aluminium Connector Fits Most Cases Seamlessly And Resists Corrosion For Signal Purity|Micro Usb 55 Cable Offers Universal Compatibility As It Is Compatible With Most Android Smartphones, Tablets, Pc Peripherals, Bluetooth Speakers, Power Banks, Game Consoles & All Micro-Usb Enabled Devices|2 years warranty from the date of purchase | J8: AG7C6DAADCTRQJG2BRS3RIKDT52Q,AFU7BOMPVJ7Q3TTA4G67RASTGYIQ,AER5ZGIXXVYG3AWZTRZT7M2BYCEA,AHE76XQSOLGOP5ZEKTIW6KUPDWBQ,AGXTMB2XHZBEWZ2UIX7ODZ4XTU6Q,AHNM2XVU745EDPNGUOAG74PTSNRA,AH5RWQ4S72IVLZD6O75OPCFIVDXQ,AG322TYKVPLPBDXE7ABEUK5QTALQ | K8: Vivek kumar,Amazon Customer,SARTHAK,Chiranjeevi,V V GIRI KUMAR,Rajnandini,Akshay Talla,sudhanshu chaubey | L8: R8E73K2KWJRDS,RSD0JTIIWQQL8,R64CRSTE9SLW1,R2FRTNIIUFJE1F,RWGNX3W7UOJ7W,R32TYHHODHTF5D,RQL9ZMQUTY7P2,R280XJ5VZUBOXV | M8: Long durable.,good,Does not charge Lenovo m8 tab,Best charging cable,good,Boat,Product was good,1.5 m à¤•à¤¾ à¤•à¥‡à¤¬à¤² à¤®à¥‡à¤°à¥‡ à¤²à¤¿à¤ à¤¬à¤¹à¥à¤¤ à¤¹à¥€ à¤²à¤¾à¤­à¤¦à¤¾à¤¯à¤• à¤¹à¥ˆ à¥¤ | N8: Build quality is good and it is comes with 2 year warranty.,Good Product,Bought it for charging my mobile & tab but it doesn't work for Lenovo m8 tab,Guys this cable is is best compare of everyone over heat protection, quickly charging, but chance to shock circuit,good,Nice,Good quality,1.5à¤à¤® à¤•à¤¾ à¤¡à¤¾à¤Ÿà¤¾ à¤•à¥‡à¤¬à¤² à¤®à¥‡à¤°à¥‡ à¤²à¤¿à¤ à¤¬à¤¹à¥à¤¤ à¤¹à¥€ à¤²à¤¾à¤­à¤¦à¤¾à¤¯à¤• à¤¹à¥ˆ à¥¤ à¤®à¥ˆà¤‚ à¤‡à¤¸ à¤•à¥‡à¤¬à¤² à¤•à¥‹ à¤²à¤¾à¤‡à¤¨ à¤®à¥‡à¤‚ à¤šà¤¾à¤°à¥à¤œ à¤•à¤°à¤¤à¥‡ à¤¸à¤®à¤¯ à¤«à¥‹à¤¨ à¤¬à¤¹à¥à¤¤ à¤†à¤°à¤¾à¤® à¤¸à¥‡ à¤‰à¤ªà¤¯à¥‹à¤— à¤•à¤° à¤ªà¤¾ à¤°à¤¹à¤¾ à¤¹à¥ à¥¤ à¤†à¤ª à¤‡à¤¸ à¤•à¥‡à¤¬à¤² à¤¸à¥‡ 15watt à¤•à¤¾ à¤šà¤¾à¤°à¥à¤œà¤° à¤‰à¤¸à¥‡ à¤•à¤° à¤¸à¤•à¤¤à¥‡ à¤¹à¥ˆ (à¤‡à¤¸à¤¸à¥‡ à¤œà¤¡à¤¼à¤¾ à¤¨à¤¹à¥€) à¥¤ à¤²à¥‹à¤•à¤² à¤¬à¤¾à¤œà¤¾à¤° à¤®à¥‡à¤‚ à¤‡à¤¸à¤•à¤¾ à¤¦à¤¾à¤® 150 à¤¹à¥ˆ , à¤…à¤®à¥‡à¤œà¤¨ à¤ªà¥‡ à¤¯à¥‡ à¤•à¥‡à¤¬à¤² à¤®à¥à¤à¥‡ 67 à¤®à¥‡à¤‚ à¤®à¤¿à¤²à¤¾ à¥¤ à¤—à¤°à¥à¤µ à¤¸à¥‡ à¤•à¤¹à¥‹ à¤¹à¤® à¤¹à¤¿à¤‚à¤¦à¥‚ à¤¹à¥ˆ , à¤œà¤¯ à¤¹à¤¿à¤‚à¤¦ à¤œà¤¯ à¤­à¤¾à¤°à¤¤ , | O8: https://m.media-amazon.com/images/W/WEBP_402378-T2/images/I/41jlwEZpa5L._SX300_SY300_QL70_FMwebp_.jpg | P8: https://www.amazon.in/boAt-Micro-USB-Tangle-Free-Transmission/dp/B08WRWPM22/ref=sr_1_8?qid=1672909124&s=electronics&sr=1-8
A9: B08DDRGWTJ | B9: MI Usb Type-C Cable Smartphone (Black) | C9: Computers&Accessories|Accessories&Peripherals|Cables&Accessories|Cables|USBCables | D9: â‚¹229 | E9: â‚¹299 | F9: 0.23 | G9: 4.3 | H9: 30411 | I9: 1m long Type-C USB Cable|Sturdy and Durable. With USB cable you can transfer data with speeds of upto 480 Mbps|Upto 3A output|6months warranty|Sturdy and Durable. With USB cable you can transfer data with speeds of upto 480 Mbps|6months warranty|Up To 3A Output | J9: AHW6E5LQ2BDYOIVLAJGDH45J5V5Q,AF74RSGCHPZITVFSZN76K6GKPICA,AHDD7ZNB47QA2JLYU53HD4ML3VNQ,AHV3ELGDSOWBYUQLXSPDCSHBQRHQ,AEJU4L3ZM2GTILSJZZSNSF6VUOIA,AFVD66VQMSHPDT3A6HBBBGKRXBZA,AELKHQXVSSG6NHXLFJLLNEFRQQUQ,AGYSMAC6V6RFJJOHG2FIRPOZ6CSQ | K9: Pavan A H,Jayesh bagad,Shridhar,rajendran,karuppu k,Akshay wani,Abbimaniu Singh,VISHAL H BADSHE | L9: R2X090D1YHACKR,R32ZCIH9AFNJ60,R3N57EVVG0EHAF,R3QWLE8JHROKC1,R2VTSDOOUTSQ5X,R3E6FZ75Q074KH,R1SYBQLTPFCW20,RYQT96J8HPIXE | M9: Worth for money - suitable for Android auto,Good Product,Length,Nice,Original,Very good quay Cable support fast charging.,Original MI cable for charging upto 33 watt,I am veri happy with this product as it provide turbo charging. | N9: Worth for money - suitable for Android auto... my purpose served in car....got it for Rs.150,Everything is Okay. But packaging is not good feeling like seller gave is used cable.,Good product,Good product but cost is more.,Original cable,I bought this cable at 129. Using this cable for Android auto in my car. Perfectly works without any glitch.,Original MI cable. Will charge upto 33 watts. Got it for Rs 150. I have 67 watt charger and I want a cable for my car so I went for it. I checked the performance with battery charging app. The charging speed is exactly half of my 67 watt original cable. Go for it.,It provided me turbo charging. I recommend for all Redmi note 10s mobile phones. As it provide turbo charging. I am veri happy with this product. | O9: https://m.media-amazon.com/images/I/31XO-wfGGGL._SX300_SY300_QL70_FMwebp_.jpg | P9: https://www.amazon.in/MI-MTCY001IN-USB-Type-C-Cable/dp/B08DDRGWTJ/ref=sr_1_9?qid=1672909124&s=electronics&sr=1-9
A10: B008IFXQFU | B10: TP-Link USB WiFi Adapter for PC(TL-WN725N), N150 Wireless Network Adapter for Desktop - Nano Size WiFi Dongle Compatible with Windows 11/10/7/8/8.1/XP/ Mac OS 10.9-10.15 Linux Kernel 2.6.18-4.4.3 | C10: Computers&Accessories|NetworkingDevices|NetworkAdapters|WirelessUSBAdapters | D10: â‚¹499 | E10: â‚¹999 | F10: 0.5 | G10: 4.2 | H10: 179691 | I10: USB WiFi Adapter â€”â€” Speedy wireless transmission at up to 150Mbps ideal for video streaming or internet calls|Mini Design â€”â€” Sleek miniature design so small that once plugged in, can be left in a Laptopâ€™s USB port|Advanced Security â€”â€” Supports 64/128 WEP, WPA, PA2/WPA-PSK/WPA2-PSK(TKIP/AES)|Compatibility â€”â€” Windows 11/10/8.1/8/7/XP, Mac OS 10.15 and earlier, Linux|Easy Setup â€”â€” Connect in no time with easy setup utility in 14 languages|In an unlikely case of product quality related issue, we may ask you to reach out to brandâ€™s customer service support and seek resolution. We will require brand proof of issue to process replacement request | J10: AGV3IEFANZCKECFGUM42MRH5FNOA,AEBO7NWCNXKT4AESAN443HQH35FQ,AE7GD3VRRYQEAHDR7FXJIR23INYA,AHPAW24BI5X2GCX5M2LHI72VSJJQ,AE2VXY4CFO36MDSIMPG43XHNF4GA,AHHQEKUNVETALN7DTRHUQ2WAWEKQ,AFMIFTNTUD5PIHGONWOTRMMZ5EBA,AHOJBIZVVIIFJKRREY4B6ESVA4KA | K10: Azhar JuMan,Anirudh Sood,Hari Krishnan PS,Akash Jindal,PRADEEP,Rajesh,Divya Kothari,abhijit | L10: R1LW6NWSVTVZ2H,R3VR5WFKUS15C5,R2F6GC79OYWUKQ,R3QZ19MECGWG9A,R2MPU42MYK7GPO,R33DVXFB4VYPZZ,R1SQ7OGFR4JRUR,R1S5F9QI0M1VBZ | M10: Works on linux for me. Get the model with antenna.,Does what it say but other brands available at lesser price,Easy Handle,Great product,Perfect working,Speed is perfect,Great Design, Build, Connectivity Range, Packaging and other features but no linux support since v2,Very good | N10: I use this to connect an old PC to internet. I tried lubuntu 20 and ubuntu 22, it worked out of the box in both, didn't have to do any setup. There's an extender cable so you can place this in a comfortable place. Get the model with antenna because otherwise you'll have range problems if you're not directly in line of sight from your wifi router.,The wifi dongle is a simple plug & play device, will start catching available networks right after you plug it into your USB port, no additional installations/ softwares requires. Signal strength is good.... just wonder what would be different in other adapters of lesser known brands which are available at a much more competitive pricing, hence a star less.,Pros:*Easy to use & Portable*Can be connected to Mobile Hotspot and used in PC( Budget Friendly)*Less installation process*No heating issues & Good Coverage*Best alternative for USB Tethering (phone's battery may get damaged for long term run with Tethering)Cons:*Internet connection speed varies at times, also depends on your modem or cellular connection*Issues occur while installing via CD, which is available along with the product( Installation driver can be downloaded from TP-Link site)*Needed to reconnect the adapter every time system is turned ON*Will not work if your software has some issues, so encountered any just update your system(worked for me)*Support Center is worse, calls are unattended most of the times or just visit nearby storeConclusion:Brought this @499/-Ideal for users who don't need very high speed internet usage,a good alternative for USB Tethering and are on Budge(1080p Youtube videos can be easily played with this without any interruptions),wifi connectivity is a great good result for me. however, some jitter problems did exist.,This is perfect device to connect wifi. Go for it.,This wifi adopter is good working,(Pictures attached)Size/Design: â˜… â˜… â˜… â˜… â˜…Build Quality: â˜… â˜… â˜… â˜… â˜…Packaging: â˜… â˜… â˜… â˜… â˜…Software: â˜… â˜… â˜… â˜…Speed: â˜… â˜… â˜… â˜… â˜…Connectivity: â˜… â˜… â˜… â˜… â˜…Experience: â˜… â˜… â˜… â˜… â˜…Warranty: â˜… â˜… â˜… â˜… â˜…Size and Design:The best part about this is that it is very compact in size and very sober and elegant in design. This is a big plus as it is easy plug in and use, add to it the good sober design.Build Quality:The build quality is undoubtedly superb. Just no qualms about that, at all. When held, it doesnt give off that cheap and flimsy product-like feeling. It is good sturdy with its build quality.Packaging:This part is also a big plus as the item was well cushioned and packaged with all the necessary items that ensured that no damage could have been caused to the product during transportation. This ensures that I as a customer have received something not damaged internally already.Software:This is actually good but not great part with the product.The good part is that a CD has been provided with it along with a manual.The not great part is that NO LINUX SUPPORT has been given from Version 2 onwards. This is bad, really.Speed:It easily supports net speeds upto 300 Mbps. Practically speaking, I have tested it at my home and it easily supports net speed of over 100-150 Mbps without a sigh.On testing I found that it did connect to 5GHz network, without any issue.Connectivity:Please mark its not feet its metres. Multiply metres x 3 to get the distance in feet.It easily connects to my laptop or phone from 7 metres across one room. So thats 21 feet. I mean even our old bluetooth used to connect to about 15 ft.So 20-25 feet is not at all an issue with this. This is the big plus I found with the product.Experience:From this point of view, so far except the linux non-compatibility issue, I found no other flaws with this product.So overall its a great product.Warranty:Its 3 years so I am assured that atleast for 3 years I am tension-free and not just 1 year, contrary to most electronic items today that only provide 1 year warranty with their items.,Best adapter I have bought ever. Works nicely seemless connectivity | O10: https://m.media-amazon.com/images/W/WEBP_402378-T2/images/I/31e6ElWRymL._SX300_SY300_QL70_FMwebp_.jpg | P10: https://www.amazon.in/TP-Link-TL-WN725N-150Mbps-Wireless-Adapter/dp/B008IFXQFU/ref=sr_1_10?qid=1672909124&s=electronics&sr=1-10
A11: B082LZGK39 | B11: Ambrane Unbreakable 60W / 3A Fast Charging 1.5m Braided Micro USB Cable for Smartphones, Tablets, Laptops & Other Micro USB Devices, 480Mbps Data Sync, Quick Charge 3.0 (RCM15, Black) | C11: Computers&Accessories|Accessories&Peripherals|Cables&Accessories|Cables|USBCables | D11: â‚¹199 | E11: â‚¹299 | F11: 0.33 | G11: 4 | H11: 43994 | I11: Universal Compatibility â€“ It is compatible with all Micro USB enabled devices, be it an android smartphone, tablet, PC peripheral or any other micro USB compatible device|Unbreakable â€“ Made of special braided outer with rugged interior bindings, it is ultra-durable cable that wonâ€™t be affected by daily rough usage|Ideal Length â€“ It has ideal length of 1.5 meters which is neither too short like your typical 1meter cable or too long like a 2meters cable|Supports maximum 3A fast charging and 480 Mbps data transfer speed|6 Months manufacturer warranty from the date of purchase. | J11: AECPFYFQVRUWC3KGNLJIOREFP5LQ,AGYYVPDD7YG7FYNBXNGXZJT525AQ,AHONIZU3ICIEHQIGQ6R2VFRSBXOQ,AFPHD2CRPDZMWMBL7WXRSVYWS5JA,AEZ346GX3HJ4O4XNRPHCNHXQURMQ,AEPSWFPNECKO34PUC7I56ITGXR6Q,AHWVEHR5DYLVFTO2KF3IZATFQSWQ,AH4QT33M55677I7ISQOAKEQWACYQ | K11: ArdKn,Nirbhay kumar,Sagar Viswanathan,Asp,Placeholder,BharanI,sonia,Niam | L11: RGIQEG07R9HS2,R1SMWZQ86XIN8U,R2J3Y1WL29GWDE,RYGGS0M09S3KY,R17KQRUTAN5DKS,R3AAQGS6HP2QUK,R1HDNOG6TO2CCA,R3PHKXYA5AFEOU | M11: A Good Braided Cable for Your Type C Device,Good quality product from ambrane,Super cable,As,Good quality,Good product,its good,Good quality for the price but one issue with my unit | N11: I ordered this cable to connect my phone to Android Auto of car. The cable is really strong and the connection ports are really well made. I already has a Micro USB cable from Ambrane and it's still in good shape. I connected my phone to the car using the cable and it got connected well and no issues. I also connected it to the charging port and yes it has Fast Charging support.,It quality is good at this price and the main thing is that i didn't ever thought that this cable will be so long it's good one and charging power is too good and also supports fast charging,Value for money, with extra lengthðŸ‘,Good, working fine,Product quality is good,Good,very good,Bought for my daughter's old phone.Brand new cable it was not charging, I already repacked and requested for replacement.I checked again, and there was some green colour paste/fungus inside the micro USB connector. I cleaned with an alcoholic and starts working again.Checked the ampere of charging speed got around 1400ma-1500ma - not bad, came with braided 1.5m long cable, pretty impressive for the price.Can't blame the manufacturer.But quality issues by the distributor, they might have stored in very humid place. | O11: https://m.media-amazon.com/images/W/WEBP_402378-T2/images/I/31kj3q4SepL._SY445_SX342_QL70_FMwebp_.jpg | P11: https://www.amazon.in/Ambrane-Unbreakable-Charging-Braided-Android/dp/B082LZGK39/ref=sr_1_11?qid=1672909124&s=electronics&sr=1-11
A12: B08CF3D7QR | B12: Portronics Konnect L POR-1081 Fast Charging 3A Type-C Cable 1.2Meter with Charge & Sync Function for All Type-C Devices (Grey) | C12: Computers&Accessories|Accessories&Peripherals|Cables&Accessories|Cables|USBCables | D12: â‚¹154 | E12: â‚¹339 | F12: 0.55 | G12: 4.3 | H12: 13391 | I12: [CHARGE & SYNC FUNCTION]- This cable comes with charging & Data sync function for smartphones|[HIGH QUALITY MATERIAL]- TPE + Nylon Material to make sure that the life of the cable is enhanced significantly|[LONG CORD]- The Cable is extra thick 1.2 meter long, optimized for an easy use for your comfort at home or office|[MORE DURABLE]-This cable is unique interms of design and multi-use and is positioned to provide the best comfort and performance while using | J12: AGYLPKPZHVYKKZHOTHCTYVEDAJ4A,AGTTU64JMX722LYCN3SOWLFPKPAQ,AFWD4ZTM7473CDWARHCDQKK73MTA,AEXCQM3FDLX3YL3UJWWUIAIUJT4A,AHUKYUWRUVRTB3IQGISXWTSPAWLQ,AFWW4UEXAJH7EAB5LTMKMSGLUN2Q,AFM5JL37WY7G6MLQUI4WAXUJME7Q,AFECO24WYFOU2KL7C3DMHTEHRU7Q | K12: Tanya,Anu,Akshay,Vishal Sagara Shetty,Swatilekha Sarkar,Jithindas,IBRAHIM S,Sundaram J. | L12: R11MQS7WD9C3I0,R2AKH69XQY8BY4,R8GBOLYUN5UP6,R1AYVO4R25KJTA,R1HT6XM787V7FV,R339XJL1GMKHA3,R175VFSB2A32HG,R35T9LXYBSP09G | M12: Good for fast charge but not for data transfer,Good cable compares to local the brand.,good but doesnt last,Good product,Good Product,Good and worth it,very good material quality charging speed is 15 watt,Not a fast charger | N12: The cable is efficient in fast charging but in quick data transfer. Overall fine.,I like the usb c L shape. Nylon Shielded core wire it improves the life of the cable.,i think i buy these every 6 months or so. fast charging stops working after a while. probbly something to do with the cable design. the cable gets twisted over time and I suspect that breaks the high capacity wires inside. but i keep buying it because there arent too many options in an L shaped design,Good and durable product. Sometime the charges doesn't work on few adapters. there might be few cut off or something but works fine on apple adapter, Car charger, USB,The product is really good at affordable price.,Good and fast charging, and value for money,à®ªà¯Šà®°à¯à®³à¯ à®‰à®Ÿà¯ˆà®¯ à®•à®Ÿà®¿à®©à®¤à¯à®¤à®©à¯à®®à¯ˆà®¯à®¿à®©à¯ à®¨à®©à¯à®±à®¾à®• à®‰à®³à¯à®³à®¤à¯ à®šà®¾à®°à¯à®œà¯ à®à®±à¯à®®à¯ à®µà¯‡à®•à®®à¯ 15wat,Not a fast charger. Very slow charging with 65w. L-shape pin is very useful. | O12: https://m.media-amazon.com/images/I/31dJ+lXJq3L._SY300_SX300_.jpg | P12: https://www.amazon.in/Portronics-POR-1081-Charging-1-2Meter-Function/dp/B08CF3D7QR/ref=sr_1_12?qid=1672909124&s=electronics&sr=1-12
A13: B0789LZTCJ | B13: boAt Rugged v3 Extra Tough Unbreakable Braided Micro USB Cable 1.5 Meter (Black) | C13: Computers&Accessories|Accessories&Peripherals|Cables&Accessories|Cables|USBCables | D13: â‚¹299 | E13: â‚¹799 | F13: 0.63 | G13: 4.2 | H13: 94363 | I13: The boAt rugged cable features our special toughest polyethylene braided jacket and this unique jacket provides greater protection than anything else you have seen in its class. Round Cable|Extra tough polyethylene terephthalate cable skin ensures 10000 plus bend lifespan, stress and stretch resistance|The boAt rugged Micro USB cable is compatible with most android smartphones, windows phone, tablets, PC peripherals and other micro USB compatible devices|2.4A rapid charge, fast data transmission and rapid speed to sync your device at the speed up to 480mbps|boAt rugged micro USB cable offers a perfect 1.5 meters in length, optimized for an easy use for your comfort at home or office|2 years warranty from the date of purchase | J13: AEWAZDZZJLQUYVOVGBEUKSLXHQ5A,AG5HTSFRRE6NL3M5SGCUQBP7YSCA,AH725ST5NW2Y4JZPKUNTIJCUK2BA,AHV3TXIFCJPMS4D5JATCEUR266MQ,AGWIGDEMFIIUAOXYY2QATNBSUGHA,AFSTSLQUV4EVEXWKBOLEFHL2H5YQ,AGAKDNBHY2FKX7I4ACRGILU7QL7A,AFNWJUWJRHCC6HN52KMG5AKZY37Q | K13: Omkar dhale,JD,HEMALATHA,Ajwadh a.,amar singh chouhan,Ravi Siddan,Himanshu Goel,Udaykumar | L13: R3EEUZKKK9J36I,R3HJVYCLYOY554,REDECAZ7AMPQC,R1CLH2ULIVG5U3,R2DMKIBGFKBD6R,RC89B5IAJUTR5,R3B3DDON5FH8DS,R13WAEJDI5RS36 | M13: Good product,Good one,Nice,Really nice product,Very first time change,Good,Fine product but could be better,Very nice it's charging like jet | N13: Good product,long wire,Charges good,Nice,I bought this cable for Rs.339 worthy product for this price, i tested it in various charger adapters 33w and 18w it supports fast charging as well.,Good,Ok,I had got this at good price on sale on Amazon and product is useful with warranty but for warranty you need to go very far not practical for such a cost and mine micro to type c connector stopped working after few days only.,I like this product | O13: https://m.media-amazon.com/images/I/41SDfuK7L2L._SX300_SY300_QL70_FMwebp_.jpg | P13: https://www.amazon.in/Rugged-Extra-Tough-Unbreakable-Braided/dp/B0789LZTCJ/ref=sr_1_13?qid=1672909124&s=electronics&sr=1-13
... A283: B09PTT8DZF | B283: Lenovo USB A to Type-C Tangle-freeÂ Â Aramid fiber braidedÂ 1.2m cable with 4A Fast charging & 480 MBPS data transmission, certified 10000+ bend lifespan, Metallic Grey | C283: Computers&Accessories|Accessories&Peripherals|Cables&Accessories|Cables|USBCables | D283: â‚¹417.44 | E283: â‚¹670 | F283: 0.38 | G283: 3.9 | H283: 523 | I283: Accessibility meets universal compatibility: Engineered to be compatible with smart phones / tabs / Bluetooth speakers / power banks and any device with Type C port and matching power rating.|Dependable and sturdy: Superior quality with 1.2m Aramid fiber braided and tangle-free cable for longevity and hassle-free handling|Powerful Performance: Work on-the-go with high-speed transfer up to 480Mbps and a 4A fast charging|Simply Stunning : Ultra-modern premium metallic grey design with aluminium metallic connectors that elevates your aesthetics|Compatibility : Compatible with all Type C Devices including laptops, phones, tablets, speakers, headphones and more | J283: AHVAHTQWBVQ564OYZLFO3ABDUUMQ,AEL2DJG4RDMKBB4U7T7FB2D4QL6A,AEZLG2GOZ4US63MFG3TTGRIOWQVQ,AH5FQ2OMFSPNFEWKR7XRHAQXYDNA,AHCWB47L2VDCBKURUGKDLNC3BLAA,AHSLVN2FXVPUVWTY5Y2GW5STS5ZA,AEU3NDBYUVLPYDRFVCIY6IPVUA7A,AFH4EKSLJGS4ZDREEEO5PLDGDWUA | K283: Mohd Arshad,Yogesh Maini,YOGESH,Devaraj V,Sasikumar,Ankeet,Hemanta Das,satinder singh | L283: R3OI9NIP86EJMK,R19REKQNB6DHVK,RN8PZREKYVUCU,R7H07OI7LETQC,RFNCQH476BUID,RBRBI3TZWFXW7,R2ZR75W02IPC5C,RPUDZMSMR65WV | M283: Nice one,Not up to the mark.,Nice product working in Asus zen pro mobile,Good product ðŸ‘ðŸ‘ðŸ‘,Working everything as expected,VERY GOOD QUALITY,Lenovo USB A to Type-C Tangle-free Aramid fiber braided 1.2m cable with 4A Fast charging,Nice Products | N283: Go for it without any hesitation,Even after selecting a branded product(Lenovo), I got this cable which only works with Samsung devices but doesnâ€™t work with LG devices. Poor compatibility.,Nice experiance,,Files transfer okSuper fast charging cable goodMeets my expectation.,Very great Quality,Just purchased and using. Charging ok. Future, I can't say.,Good | O283: https://m.media-amazon.com/images/I/317Bv9KEltL._SX300_SY300_QL70_FMwebp_.jpg | P283: https://www.amazon.in/Lenovo-Tangle-free-Aramid-braided-1-2m-transmission-certified/dp/B09PTT8DZF/ref=sr_1_438?qid=1672909146&s=electronics&sr=1-438
A284: B0B94JPY2N | B284: Amazon Brand - Solimo 65W Fast Charging Braided Type C to C Data Cable | Suitable For All Supported Mobile Phones (1 Meter, Black) | C284: Computers&Accessories|Accessories&Peripherals|Cables&Accessories|Cables|USBCables | D284: â‚¹199 | E284: â‚¹999 | F284: 0.8 | G284: 3 | I284: USB C to C Cable: This cable has type C connector at both ends and a USB C type wall charger/adapter will be required to be used with this cable|Durable and sturdy: 1 meter long cable with 5mm thickness|65W fast charging up to 4A/ 65W|Comes with Smart Charge Auto Detect Technology|The cable supports data transfer at a speed of 480Mbps|Prevents overheating and overcharging with several built-in safeguards|Suitable for all major smartphones including OnePlus, Xiaomi, Realme, Oppo, etc. | J284: AE7CFHY23VAJT2FI4NZKKP6GS2UQ | K284: Pranav | L284: RUB7U91HVZ30 | M284: The cable works but is not 65W as advertised | N284: I have a pd supported car charger and I bought solimo cables previously which work perfectly fine but this one doesn't trigger full 3A fast charging unlike solimo usb a to usb c, which is strange because this is supposed to be a 65W charger with 4A fast charging support.Anyways it's a good built product and works but not as expected. It might be compatible with your chargers but I tested 2 different car chargers and both didn't go full speed. | O284: https://m.media-amazon.com/images/W/WEBP_402378-T2/images/I/41Vpx5MVtaL._SY300_SX300_QL70_FMwebp_.jpg | P284: https://www.amazon.in/Amazon-Brand-Charging-Suitable-Supported/dp/B0B94JPY2N/ref=sr_1_444?qid=1672909146&s=electronics&sr=1-444
A285: B0B3XXSB1K | B285: LG 139 cm (55 inches) 4K Ultra HD Smart LED TV 55UQ7500PSF (Ceramic Black) | C285: Electronics|HomeTheater,TV&Video|Televisions|SmartTelevisions | D285: â‚¹47,990 | E285: â‚¹79,990 | F285: 0.4 | G285: 4.3 | H285: 1376 | I285: Resolution: 4K Ultra HD (3840x2160) | Refresh Rate: 60 hertz|Connectivity: Wi-Fi (Built-in) | 3 HDMI ports to connect set top box, Blu Ray players, gaming console | 1 USB ports to connect hard drives and other USB devices | eARC | Bluetooth 5.0 | Optical | Ethernet|Sound: 20 Watts Output | 2.0 Ch Speaker | AI Sound (Virtual Surround 5.1 up-mix) | Auto Volume Levelling | Bluetooth Surround Ready|Smart TV Features: AI ThinQ & WebOS 22 with User Profiles | Game Optimizer & Dashboard | Î±5 Gen5 AI Processor 4K | Unlimited OTT App Support: Netflix, Prime Video, Disney+ Hotstar, Apple TV, SonyLIV, Discovery+, Zee5 | ALLM & HGiG Mode | HDR 10 Pro & Active HDR|Display: 4K Ultra HD LED Display | 4K Upscaler | AI Brightness Control|Warranty Information: 1 Year LG India Comprehensive Warranty and additional 1 year Warranty is applicable on panel/module from the date of purchase|Installation : For requesting installation/wall mounting/demo of this product once delivered, please directly call LG support (Please visit LG Website for Toll Free Numebrs) and provide product's model name as well as seller's details mentioned on the invoice | J285: AFCWL3MX7BP2ZUDD37MEAENZDQ2A,AGGFXDLCFZMTLJJDR3ZFKEOXCFLQ,AHEBPCKZFBKQMB6FXQLRP72OG4ZQ,AF2V6W7LKARBMZQLFL44AY6KYOCA,AGGGM5HE2PLQKZV33JOD6K2TYPQQ,AG5VQTV5OVY2Q42ZQPWXTRU2PSLQ,AFZ5KWM4MSPU25YIO2CYGGSNYV6Q,AE6THY5M7QTHCQRZ6PIUENS3NY4A | K285: Raj Mohammed,Samson,Haroon sayeed,P Imran Khan,Manohar P,SRF Prashant,Akash Sharma,Sumesh | L285: RC3ZLDRM8GA9T,RMDN4PSDM8SKK,R1YFAMDJ7P0SY3,R2WX7G1LIQSEBM,R2L4UCJ30902KF,R2MCXM8TACTRFL,R1KFS9LDEOT49N,R29FE7S1YAMO8N | M285: Love Amazon but lg is misleading,Amazing product,Worst service from LG,Good,Simply beautiful,Satisfied with the TV,Great deal,It is quite ok | N285: There's no magic remote and lg should include it by default as it makes life easier. The magic remote costs around 3k approximately.Display: when turned on tv and tested the display on black wallpaper found very small green and white dots.Immediately called up Amazon first and then we scheduled a tech visit.The tech did not come rather spoke on call and asked what's the problem and when informed about the problem he said needs to be replaced but no body came with it.So i waited for 2 days again and nothing was showing up on Amazon app about replacement so doubting it I called up Amazon customer care again and explained everything again and finally spoke to some one and she said she will get it replaced and i was given another date within 4 days.This time the replacement came and was good.,Amazing picture quality and sound clarity, but only drawback is that it did not come with a Magic remote.,The television is good but the installation service is pathetic first of all they did not contact us till 2 days after the TV delivery and we got frustrated and call LG customer service and they accepted our problem and send a technician after 2 hours and while installing the mount he installed 3 bolts successfully but he broke the last bolt and we asked him will it not cause a problem in future he said it wouldn't but we don't really believe him.,Good,Very nice good quality best in this price,Nice choice,Best deal,I like LGWorth for price. Very good | O285: https://m.media-amazon.com/images/W/WEBP_402378-T2/images/I/51dOjIreG4L._SX300_SY300_QL70_FMwebp_.jpg | P285: https://www.amazon.in/LG-inches-Ultra-55UQ7500PSF-Ceramic/dp/B0B3XXSB1K/ref=sr_1_445?qid=1672909146&s=electronics&sr=1-445
A286: B08RZ12GKR | B286: Tata Sky Digital TV HD Setup Box Remote | C286: Electronics|HomeTheater,TV&Video|Accessories|RemoteControls | D286: â‚¹215 | E286: â‚¹499 | F286: 0.57 | G286: 3.5 | H286: 121 | I286: Color black|Long lasting|Digital TV HD Setup Box Remote | J286: AHSXEBRVZO6MAYZRN6O6ZGT6TQIQ,AE3WP33376SA5IZT4Z5P25RW5SNA,AEP577REOPX5HAMEECZZKMOYZ3OQ,AHXFU2NP5EL5BNCYY3V2BOWDYX4Q,AEPLVXU6CECEGNG6EUUSHMERYNRA,AEQ7NM325SUT6YB62ZG376GF7O7Q,AEBV2AUCTSN3QJO4LJVJ66HVYSTQ,AHCLG7MIFKVJJEAVPYJPW2OPWWEQ | K286: Rajni Gupta,Lakshmipati Hari,Sriranga Pudupakkam,radha krishnan,Nandan,Dr Laksheswar Bora,Laxmi Narayan,KONGA VIJAYA NAGARAJU | L286: R1T3IMKX5I23BL,R2ACT45S9ER36B,R3JVGT39A4NCLG,R2ZS039FIJFE2X,RUE1VX5KVXKYM,RJUMN5TQXB046,RKB470J0YGFZS,R30Z26FC4CVOIK | M286: NOT GOOD IN DURIBILITY.,The remote lasted a grand total of one week.,Good product too early to say final word on durability,prompt delivery plus supet product,It's good.,satisfactory,Body problems,Damaged product | N286: It is just ok,The fist time I bought it lasted about 6 months. The second time, barely a week. Spent a little more money but went back to the original from Tata Sky. Not really going to buy this again,Good product,i like it for prompt delivery plus super touch operating t.v.,It's working as expected.,satisfactory,Weak of body,We received damaged product...there is a crack in front of the remote.....pls check n make sure this should not be repeat again... | O286: https://m.media-amazon.com/images/W/WEBP_402378-T1/images/I/41o4qDiFFwL._SX300_SY300_QL70_FMwebp_.jpg | P286: https://www.amazon.in/Tata-Sky-Digital-Setup-Remote/dp/B08RZ12GKR/ref=sr_1_447?qid=1672909146&s=electronics&sr=1-447
A287: B0B4T8RSJ1 | B287: pTron Solero T241 2.4A Type-C Data & Charging USB Cable, Made in India, 480Mbps Data Sync, Durable 1-Meter Long USB Cable for Smartphone, Type-C USB Devices (White) | C287: Computers&Accessories|Accessories&Peripherals|Cables&Accessories|Cables|USBCables | D287: â‚¹99 | E287: â‚¹800 | F287: 0.88 | G287: 3.9 | H287: 1075 | I287: Solero T241 data and charging cable is equipped with a Type-C USB port, the cable supports up to 2.4Amps of power output for powering and fast charging your smart device.|Charge & sync, this USB cable can charge and data sync simultaneously at 480Mbps speed, compatible with all devices with a C-Type USB port.|Durable PVC Outer Exterior: PVC cables are versatile, high in tensile strength, flexible, and good conductors.|pTron Solero T241 Type-C USB cable is 1 meter in length, optimized for easy use for your comfort at home or office, helps you to overcome distance restrictions.|This data and charging C-type USB cable has gone through scientific tests like 5000 times USB insert, 24 hours salt spray, and 10000+ bend life span which ensures long service life. | J287: AF477BP57JM7Z4JD4PYB2K33R6AQ,AGTDD34Y77OB36JNYQWQDN7MHECQ,AG7POKBSWQUO4VOYD4HDWYKMMJ4Q,AFZS6H2ZFJEJHRWIJ3IYL7V6KRPA,AHCYM2ECKI2MNOIDHDG4PT6IIN6A,AECZ4IP3TBM4EUG52BZAOQV3EKIA,AH6RQDXZYKAUPNBOYC4NAZERTFOQ,AFTVETL4HGH4KRUF4NXGJUEDPBAQ | K287: Placeholder,à¤¶à¥à¤°à¥€PKà¤œà¥€,Gauri salkar,aQeel,Ashish Raj Arora,Ankit,Amazon Customer,Ramamoorthy Jaykumar | L287: R1Q323BB35OP30,RJ0CSQUUWFF9W,R23OB4XMH3S9QD,R1K5FQR6CYMQAV,R3QMD6JDUGQUCI,R1R5LTMWOXI38M,R241G3F07D3OBH,R1O7BQ61DXRVWW | M287: The metal pin is losing it's strength,Sahi h bs 44 rupe ki and dilivery charge 40,Good Charging cable,Good sturdy micro usb cable with good charging speeds,Cheapest micro USB cable in the market,boat is better than this,I bought this for 199rs best charging cable for all mobiles,Good | N287: It's a good data cable and I recommend it to purchase,the only issue was the metal pin is not fixed firmly so it has become loose,otherwise no issue,must purchase,https://m.media-amazon.com/images/W/WEBP_402378-T2/images/I/615SgnWv1ML._SY88.jpg,Charging cable which is sturdy it's not a fast charging cable but the three outlets does the job.,Good sturdy micro usb cable with good charging speeds. Please don't raise prices,Nice product, a simpla microusb cable,ðŸ˜‚,Best for this price,Good one | O287: https://m.media-amazon.com/images/W/WEBP_402378-T2/images/I/31XFe74gRjL._SX300_SY300_QL70_FMwebp_.jpg | P287: https://www.amazon.in/pTron-Charging-480Mbps-Durable-Smartphone/dp/B0B4T8RSJ1/ref=sr_1_448?qid=1672909146&s=electronics&sr=1-448
A288: B0B7B9V9QP | B288: VU 108 cm (43 inches) Premium Series Full HD Smart LED TV 43GA (Black) | C288: Electronics|HomeTheater,TV&Video|Televisions|SmartTelevisions | D288: â‚¹18,999 | E288: â‚¹35,000 | F288: 0.46 | G288: 4 | H288: 1001 | I288: Resolution : Full HD (1920x1080) | Refresh Rate : 60 Hertz | 178 Degree wide viewing angle|Connectivity: 2 HDMI ports to connect set top box, Blu-ray speakers or gaming console | 2 USB ports to connect hard drives or other USB devices|Sound: 20 Watts output | Dolby Audio | DTS HD | Bass Boost | Dialog Clarity | TruVolume|Smart TV Features : Netflix | Prime Video | YouTube | YouTube Music | Zee5 | Wake up on LAN, WiFi | Wireless IEEE 802.11: b, g, n, 2.4GHz | Screen Mirrioring|Display : A+ Grade High Bright Panel I Natural Color Enhancer I Adaptive Contrast I Clear Motion I 1:1 Pixel Mapping I Cinema Day & Night Mode I Game Mode I Sports Mode I MPEG Noise Reduction|Warranty Information: 1 year warranty provided by Vu from date of purchase|Installation Information : Installation/Wall mounting/Demo will be arranged by AHS Team. For any other information, please contact VU support on (visit brand website for toll-free numbers)|Easy Returns: This product is eligible for replacement within 10 days of delivery in case of any product defects, damage or features not matching the description | J288: AHQCV7O3JOMFFMD7EGIZ2NGSU6JQ,AGTB6FEDSOBJNAVZSDSY73YUVTXQ,AFHULRP4IR7O4FQKWKI266O7VZQQ,AFKYLJ2CLPR7FIWD2MBXNIER7R3A,AFJRW562LETJUBBZYVI6VZA35WPQ,AEEMPL2VIRNJTYATMFPHFSHI4IOA,AGKQQC7ST26N5VFAHMURX3R2RAJA,AFICI6GI5DCTRS6JVCYRPATIPXSQ | K288: Logaraj m,KIRAN KUMAR GUDLA,Sandeep Kumar,Jaydeep Shah,Nagendra,Sumit pandey,Harsh Bhatia,Sivakrishna | L288: R22OHRDXFQ2O98,RSAB4HSG5ZH9H,R3FC8NLEZ4DJ8N,R1RTOHK5EM9WPX,RFVPFUT2AVH9A,R232XWKJREFG9M,RZAZ7VZRRHLFH,R1CEPOZCGKCSWH | M288: Vu brand superb quality,Value for price,Thik hai but android nahi hai,Good model for entry level 32" TV need.,Good product value of Money,Great TV,The sound quality, speakers, picture quality are just OK. MID GRADE PRODUCT AT MOST,Picture Quality | N288: Super,Good Quality , value for money.. in time installed,Tv thik hai but vu ka customer support bhot bekar hai , bacho se tv lock ho gya tha , vu me call kia to kahne lage Amazon me baat karo , matlb tv ka lock Amazon wale batenge , Amazon me baat ki to kahte hai vu me baat karo , baad me maine hi kisi tarah uska lock khola , but vu customer support bhot bekar hai , vu ka smart tv thik hai,In time delivery and proper installation at the time of delivery itself. Value for money for 32" TV requirement with branded product.,Good product,Tv is awesome, one problem is casting, whey you cast video from hotstar it comes black screen. Other than that picture and sound quality is awesome.,Picture quality Just OK. Sharpness missingSound and speakers Need lot of improvementSettings and Menu can be optimised furtherOverall it's a mid grade product,Picture quality good as expected, internet experience also good | O288: https://m.media-amazon.com/images/I/51eyIMn02bL._SX300_SY300_QL70_FMwebp_.jpg | P288: https://www.amazon.in/VU-inches-Premium-Smart-43GA/dp/B0B7B9V9QP/ref=sr_1_449?qid=1672909146&s=electronics&sr=1-449
A289: B08XXVXP3J | B289: Storite Super Speed USB 3.0 Male to Male Cable for Hard Drive Enclosures, Laptop Cooling Pad, DVD Players(60cm,Black) | C289: Computers&Accessories|Accessories&Peripherals|Cables&Accessories|Cables|USBCables | D289: â‚¹249 | E289: â‚¹999 | F289: 0.75 | G289: 4.3 | H289: 112 | I289: Cable Color- Black , Cable Length- 60 cm , Connector Type - USB Type A Male to Type A Male|Premium quality SuperSpeed USB 3.0 Type A to A M/M device cables|Double-shielded, twisted-pair data wiring minimizes cross talk for error free SuperSpeed data transfer rates Support data transfer rates up to 4.8Gbps|Backwards compatible with computer USB 2.0 and USB 1.1 ports - these cables also allow connection of USB 3.0 devices to legacy USB 2.0 computers|PLUG & PLAY : No driver needed for the usb 3.0 a to a cable. Just plug-and-play for hard drive enclosures, printers, modems, cameras, and other SuperSpeed USB peripherals.349-699 | J289: AEOHCZKNWRXT3H4Q66WMEMB672IA,AGUSIMQLSTJXNHNX4OT5KEJZO2NQ,AFLVRNJ3FWTYVR2QR7LMMAXOR2VQ,AGYNRF4LKWIYRL2EOCVDINQ62RAQ,AHUGZ3YEQ27J3KSESPRFRAKNF3LA,AGBP6M4EOJSBHZTYTH2T4BKNJ7MQ,AECZ7LYEACIXJTSOCFWLHVZLJPEA,AHOHKZ6CPYXLBXPKLZCDT7HHD6CA | K289: Shilpa M,Akash,Aman.MD,Manoj Yadav,Ashutosh,Patel,Saikrushna Dyaga,Amazon Customer | L289: RDLKA670FVMKY,RZZB1IDY3USBP,R30B6VRIVHWOIP,R31A5RDIAY3O0R,R26RJ6WBBMVVXJ,R1PZ0SMCXPJO9C,R3QLX0DTF1C3J7,R23GQW7DPSVOA0 | M289: Product life ia short,Good,Waste,Value for money,Very nice product at a reasonable price. Value for money.,Good replacement cable at this price,Worst cable. Not working even after replacement. Dont buy guys Manufactured in China.,Not working | N289: Good and easy to use but product life is hell short. It means you have to buy it within next six months.,Good,Better,Quality is good and working as expected.,,Decent replacement cable for my aging external hdd. Works at usb 3.0 speeds,Worst cable. Not working even after replacement. Dont buy guys Manufactured in China.,The USB cable was useless. After logging in this cable, I was not able to transfer data from one laptop too another. | O289: https://m.media-amazon.com/images/I/41XgWuRRNFL._SX300_SY300_QL70_FMwebp_.jpg | P289: https://www.amazon.in/Storite-USB-3-0-Transfer-Enclosures/dp/B08XXVXP3J/ref=sr_1_450?qid=1672909146&s=electronics&sr=1-450
A290: B06XGWRKYT | B290: Kodak 80 cm (32 Inches) HD Ready LED TV Kodak 32HDX900S (Black) | C290: Electronics|HomeTheater,TV&Video|Televisions|StandardTelevisions | D290: â‚¹7,999 | E290: â‚¹15,999 | F290: 0.5 | G290: 3.8 | H290: 3022 | I290: Resolution: HD Ready (1920 * 1080) | Refresh Rate: 60 Hertz|Connectivity: 2 HDMI ports to connect set top box, Blu Ray players, gaming console | 2 USB ports to connect hard drives and other USB devices | 1 VGA Port to connect the laptop|Sound: 20 Watts Output | Audio Boost 20 watts Output|Display: HD Ready | Dynamic Picture Enhancement | Wide Viewing | Perfect Panel | Sleek & Sophisticated Design|Easy returns: This product is eligible for replacement within 10 days of delivery in case of any product defects, damage or features not matching the description provided | J290: AHILWO2P2PT6EKK2HS4EALRJIQ7Q,AGBF4IFXPQPS3KTL2RET4NAYKSZA,AF3WE2A3BJW3ZK2XTUU7GTQ5P2IA,AGWS7K3SXNU4RJUBPYYEVO76HULQ,AGDSPVKPPJG2FSNEYACD45GIJ7WQ,AFSG7IWPY64B6DNMUDVXYCEK4G4A,AGABMXBJYA3LSM5LIRNXL3HMHTLA,AHBNWKWV73LMUFENL6T43ZEP2ASQ | K290: Sandip Shingrakhia,Abhishek Gagan,dasprathap,Pradeep,DrChirag Rajpara,Atanu Sarkar,Puja Das,Shankar | L290: R20Y7L8T8S0B2V,R19O1AZBIG1F5P,R1HA5IN5GZZEKJ,R3BGLBQWLQUBW0,R2GKH9JNW12AKY,RKEC16QEHA2WT,R1A9NXDM3RASAL,R25TUXKCEEATJ0 | M290: This is a Best kodak LED,Product is Good as per the price but customer service experience is too bad,It's ok,Company doesn't provide Installation.Demand change for it.,Good but not best,Good product ðŸ‘,Very nice,Display quality and incomplete product | N290: ,Product is Good as per the price but customer support team is very bad, asking for money for installation and the most important thing that customer service team have not good manner/behaviour to handle the customer...1 star for them, if possible then start should be in minuse for them.,It's ok,Everything is ok,I have used Kodak 32" led tv since last 3 year and running well so i want to purchasesame tv again (same model number) but when new tv received i notice that outer body is not so durable and have no volume or menu switch in new one!! (Old one habe 6 keys on right side panel) only have one on off switch.. Others in remote only!!Now lets see how many years it runs... +Point is it has optical port (thomsan and kodak both mfg by simtronic india ltd),Picture and sound quality is very good. Allover nice product. Vallu for money.,Very nice,VGA port is not present, display quality is not good. | O290: https://m.media-amazon.com/images/I/51xYKHUpdHL._SY300_SX300_QL70_FMwebp_.jpg | P290: https://www.amazon.in/Kodak-inches-32HDX900S-Ready-Black/dp/B06XGWRKYT/ref=sr_1_451?qid=1672909146&s=electronics&sr=1-451
A291: B07CWDX49D | B291: AmazonBasics Double Braided Nylon USB Type-C to Type-C 2.0 Cable, Charging Adapter, Smartphone 6 feet, Dark Grey | C291: Computers&Accessories|Accessories&Peripherals|Cables&Accessories|Cables|USBCables | D291: â‚¹649 | E291: â‚¹1,600 | F291: 0.59 | G291: 4.3 | H291: 5451 | I291: Connect USB Type-C enabled devices (MacBook, Chromebook Pixel, Galaxy Note 7, etc.) with standard USB Type-C 2.0 enabled devices and accessories (smartphones, car/wall charger, multi-port adapters, etc.)|Ideal for charging and powering USB Type-C enabled devices, as well as syncing data, photos, and music; Type-C port is half the width and one-third the height of a standard USB-A connector (slightly larger compared to Lightning or Micro-USB ports)|Reversible designâ€”easily insert the connector into any Type-C enabled device (does not matter which side is up)|Durable braided nylon fiber cloth provides protection, strength, and flexibility; added layer of protection for improved durability and to reduce fraying; cables have been tested to bend 95-degrees 5,000 times; fun contemporary color options for a trendy appearance|Up to 480 Mbps data transfer speed; power output up to 5V, 3 amp; certified by USB-IF to be compliant with USB 2.0|1 year limited warranty | J291: AGPOYBESW4JLTMELJLGMLV4JKJEA,AGJ2XZ2PPFHMYQ54KPSUGDLHTOIA,AEPLOFVKFHPQH4DFHKQXGKWL24NQ,AEXK3LPRGQWVMCIQZGHHJUBHHAZA,AG3J2PDHKL63SV6RT5SZKPHEJM7A,AHNO42W4KBB6YAKX3VZKVCLI67DQ,AEGCEHUVRPOYDRJHI4UJVB2XY6FA,AEQ5ZXLEZFYS2Q7GBBW6IDJTH5GQ | K291: Gaurab Chakraborty,Pratik Patel,Rahul sharma,SEKAR,Nilesh Madhani,Saurabh Dongre,s s.,Sumit jogade | L291: R2BUNT9GM6PUP1,R2Q5VBGDJQHT1E,R1CICFI88LJ1JV,RVYACTR72CHW1,R2XM5RGIHDDR05,RJZUZ9HFCXQSD,R16G8AJOJIMF8H,R10M9KZFIDFMAD | M291: Overall it's a good product for mobile charging.,Awesome ðŸ˜Ž,Gud data cabel....,Very good USB C TO USB C Cable .The one does not entangle to develop fold leading to cracks and cuts,Best,Rigid and high quality,Super durable,Great i have been using for 6 month | N291: Good product ðŸ‘ðŸ»,Nice products and easy to use.very good quality and the product is very good ðŸ˜Š,,Simply Go for it.I have been using this almost for the last 1.5 years. I have been using this every day, the whole day during office hours, and sometimes work at home both for my Phone and Laptop using with 65-watt charger.It is trouble-free and does its job as we expect it to do. No problem whatsoever.The big plus point with this cable is that it does not entangle to develop constant fold that becomes cracks over a period of time. This is the issue that I had with other cables. This one is perfect.As I said, You can simply go for it. Strongly recommended.,Best,The length could have been longer,Value for money,Godd quality material and fast charging | O291: https://m.media-amazon.com/images/W/WEBP_402378-T1/images/I/41AUgZQAs5L._SX300_SY300_QL70_FMwebp_.jpg | P291: https://www.amazon.in/AmazonBasics-Double-Braided-Nylon-Type-C/dp/B07CWDX49D/ref=sr_1_452?qid=1672909146&s=electronics&sr=1-452
